Workbook

Sheet 使用前须知
A1: 本卡牌库初始数据源于原A岛的“一点山河笔，万界翡翠梦”
A2: 1.库内数据系各位匿名肥哥提供，请勿轻易修改他人数据（无描述的可自由添加）
A3: 2.自觉遵守匿名原则，请勿使用任何让他人造成困扰的操作，包括但不限于删除数据、胡言乱语等
A4: 3.本牌库内容的应用遵守以下CC BY-NC 4.0协议(署名-非商业性使用)，署名仅要求标注“灵感来源A岛公共牌库”或“灵感来源A岛”
A7: 署名-非商业性使用 4.0 国际版 (CC BY-NC 4.0)
A8: 这是一份易于普通人阅读与理解的许可证文本（并非法律性质的授权条款的替代内容）。
A10: 你可以自由地：
A11: 1.分享 – 在任何媒介或格式下再分发、传播本创作。
A12: 2.修改 – 重混、转换、依据本创作进行再创作。
A13: 3.只要遵守下述条款规定，授权人将不能撤回你使用本创作的自由。
A15: 唯须遵循以下条款：
A16: 1.署名 – 你必须以给予姓名标注，并提供本许可证的链接。同时你需要声明公开的创作是否经过修改。你可以采用恰当的形式将相关信息表述出来，但不得以任何形式暗示授权人已正式认可了你以及你的使用行为。
... A22: 不提供保证。本授权协议并不能完全提供你预期需要的所有许可，例如：公共形象权，隐私权，著作人身权等其他权利，这些权利的法律限制可能会限制你使用本创作。

Sheet 使用前须知 (2)
A1: 本卡牌库初始数据源于原A岛的“一点山河笔，万界翡翠梦”
A2: 1.库内数据系各位匿名肥哥提供，请勿轻易修改他人数据（无描述的可自由添加）
A3: 2.自觉遵守匿名原则，请勿使用任何让他人造成困扰的操作，包括但不限于删除数据、胡言乱语等
A4: 3.本牌库内容的应用遵守以下CC BY-NC 4.0协议(署名-非商业性使用)，署名仅要求标注“灵感来源A岛公共牌库”或“灵感来源A岛”
A7: 署名-非商业性使用 4.0 国际版 (CC BY-NC 4.0)
A8: 这是一份易于普通人阅读与理解的许可证文本（并非法律性质的授权条款的替代内容）。
A10: 你可以自由地：
A11: 1.分享 – 在任何媒介或格式下再分发、传播本创作。
A12: 2.修改 – 重混、转换、依据本创作进行再创作。
A13: 3.只要遵守下述条款规定，授权人将不能撤回你使用本创作的自由。
A15: 唯须遵循以下条款：
A16: 1.署名 – 你必须以给予姓名标注，并提供本许可证的链接。同时你需要声明公开的创作是否经过修改。你可以采用恰当的形式将相关信息表述出来，但不得以任何形式暗示授权人已正式认可了你以及你的使用行为。
... A22: 不提供保证。本授权协议并不能完全提供你预期需要的所有许可，例如：公共形象权，隐私权，著作人身权等其他权利，这些权利的法律限制可能会限制你使用本创作。

Sheet 汇总(保护)
A1: 类型 | B1: 总计 | C1: 计划数 | L1: 白色品质
A2: 白卡 | B2: =COUNTA(白卡!A:A)-1 -> 424 | C2: /500 | D2: 严重不足 | L2: 编号 | M2: 类型 | N2: 名称 | O2: 描述
A3: 绿卡 | B3: =COUNTA(绿卡!A:A)-1 -> 601 | C3: /200 | D3: √ | L3: =RANDBETWEEN(2,(LARGE(白卡!A:A,1)+1)) -> 72 | M3: 生物 | N3: =IF(INDIRECT("白卡!B"&(INDIRECT("$L$3")+1))="生物",INDIRECT("白卡!C"&(INDIRECT("$L$3")+1)),"请刷新") -> 请刷新 | O3: =IF(INDIRECT("白卡!B"&(INDIRECT("$L$3")+1))="生物",IF(INDIRECT("白卡!D"&(INDIRECT("$L$3")+1))>0,INDIRECT("白卡!D"&(INDIRECT("$L$3")+1)),"（无描述）"),"请刷新") -> 请刷新
A4: 蓝卡 | B4: =COUNTA(蓝卡!A:A)-1 -> 477 | C4: /150 | D4: √ | L4: =RANDBETWEEN(2,(LARGE(白卡!A:A,1)+1)) -> 34 | M4: 器物 | N4: =IF(INDIRECT("白卡!B"&(INDIRECT("$L$3")+1))="器物",INDIRECT("白卡!C"&(INDIRECT("$L$3")+1)),"请刷新") -> 请刷新 | O4: =IF(INDIRECT("白卡!B"&(INDIRECT("$L$3")+1))="器物",IF(INDIRECT("白卡!D"&(INDIRECT("$L$3")+1))>0,INDIRECT("白卡!D"&(INDIRECT("$L$3")+1)),"（无描述）"),"请刷新") -> 请刷新
A5: 紫卡 | B5: =COUNTA(紫卡!A:A)-1 -> 231 | C5: /100 | D5: √ | L5: =RANDBETWEEN(2,(LARGE(白卡!A:A,1)+1)) -> 364 | M5: 场所 | N5: =IF(INDIRECT("白卡!B"&(INDIRECT("$L$3")+1))="场所",INDIRECT("白卡!C"&(INDIRECT("$L$3")+1)),"请刷新") -> 大规模林场 | O5: =IF(INDIRECT("白卡!B"&(INDIRECT("$L$3")+1))="场所",IF(INDIRECT("白卡!D"&(INDIRECT("$L$3")+1))>0,INDIRECT("白卡!D"&(INDIRECT("$L$3")+1)),"（无描述）"),"请刷新") -> （无描述）
A6: 橙卡 | B6: =COUNTA(橙卡!A:A)-1 -> 102 | C6: /45 | D6: √ | L6: =RANDBETWEEN(2,(LARGE(白卡!A:A,1)+1)) -> 339 | M6: 事件 | N6: =IF(INDIRECT("白卡!B"&(INDIRECT("$L$3")+1))="事件",INDIRECT("白卡!C"&(INDIRECT("$L$3")+1)),"请刷新") -> 请刷新 | O6: =IF(INDIRECT("白卡!B"&(INDIRECT("$L$3")+1))="事件",IF(INDIRECT("白卡!D"&(INDIRECT("$L$3")+1))>0,INDIRECT("白卡!D"&(INDIRECT("$L$3")+1)),"（无描述）"),"请刷新") -> 请刷新
A7: 虹卡 | B7: =COUNTA(虹卡!A:A)-1 -> 38 | C7: /5 | D7: √ | L7: =RANDBETWEEN(2,(LARGE(白卡!A:A,1)+1)) -> 272 | M7: 概念 | N7: =IF(INDIRECT("白卡!B"&(INDIRECT("$L$3")+1))="概念",INDIRECT("白卡!C"&(INDIRECT("$L$3")+1)),"请刷新") -> 请刷新 | O7: =IF(INDIRECT("白卡!B"&(INDIRECT("$L$3")+1))="概念",IF(INDIRECT("白卡!D"&(INDIRECT("$L$3")+1))>0,INDIRECT("白卡!D"&(INDIRECT("$L$3")+1)),"（无描述）"),"请刷新") -> 请刷新
A8: 黑卡 | B8: =COUNTA(黑卡!A:A)-1 -> 32 | L8: 绿色品质
A9: 总卡数 | B9: =SUM(B2:B8) -> 1905 | L9: 编号 | M9: 类型 | N9: 名称 | O9: 描述
L10: =RANDBETWEEN(2,(LARGE(绿卡!A:A,1)+1)) -> 89 | M10: 生物 | N10: =IF(INDIRECT("绿卡!B"&(INDIRECT("$L$10")+1))="生物",INDIRECT("绿卡!C"&(INDIRECT("$L$10")+1)),"请刷新") -> 猎犬 | O10: =IF(INDIRECT("绿卡!B"&(INDIRECT("$L$10")+1))="生物",IF(INDIRECT("绿卡!D"&(INDIRECT("$L$10")+1))>0,INDIRECT("绿卡!D"&(INDIRECT("$L$10")+1)),"（无描述）"),"请刷新") -> 神秘的调查员，他们愿意为未知的秘密付出一切。
A11: 生物 | B11: =COUNTIF(白卡!B:B,"生物")+COUNTIF(绿卡!B:B,"生物")+COUNTIF(蓝卡!B:B,"生物")+COUNTIF(紫卡!B:B,"生物")+COUNTIF(橙卡!B:B,"生物")+COUNTIF(虹卡!B:B,"生物")+COUNTIF(黑卡!B:B,"生物") -> 359 | G11: 扒卡来源 | H11: A岛串号 | J11: 如何刷新？ | L11: =RANDBETWEEN(2,(LARGE(绿卡!A:A,1)+1)) -> 349 | M11: 器物 | N11: =IF(INDIRECT("绿卡!B"&(INDIRECT("$L$11")+1))="器物",INDIRECT("绿卡!C"&(INDIRECT("$L$11")+1)),"请刷新") -> 请刷新 | O11: =IF(INDIRECT("绿卡!B"&(INDIRECT("$L$11")+1))="器物",IF(INDIRECT("绿卡!D"&(INDIRECT("$L$11")+1))>0,INDIRECT("绿卡!D"&(INDIRECT("$L$11")+1)),"（无描述）"),"请刷新") -> 请刷新
B12: 白色生物 | C12: =COUNTIF(白卡!B:B,"生物") -> 85 | D12: /100 | E12: 严重不足 | G12: 炼金团 | H12: 24584776 | J12: 1.本地文件请按F9 | L12: =RANDBETWEEN(2,(LARGE(绿卡!A:A,1)+1)) -> 465 | M12: 场所 | N12: =IF(INDIRECT("绿卡!B"&(INDIRECT("$L$12")+1))="场所",INDIRECT("绿卡!C"&(INDIRECT("$L$12")+1)),"请刷新") -> 请刷新 | O12: =IF(INDIRECT("绿卡!B"&(INDIRECT("$L$12")+1))="场所",IF(INDIRECT("绿卡!D"&(INDIRECT("$L$12")+1))>0,INDIRECT("绿卡!D"&(INDIRECT("$L$12")+1)),"（无描述）"),"请刷新") -> 请刷新
B13: 绿色生物 | C13: =COUNTIF(绿卡!B:B,"生物") -> 107 | D13: /40 | E13: √ | G13: 神格祝愿 | H13: 37839042 | J13: 2.WPS网页请点上方的 | L13: =RANDBETWEEN(2,(LARGE(绿卡!A:A,1)+1)) -> 493 | M13: 事件 | N13: =IF(INDIRECT("绿卡!B"&(INDIRECT("$L$13")+1))="事件",INDIRECT("绿卡!C"&(INDIRECT("$L$13")+1)),"请刷新") -> 锻造 | O13: =IF(INDIRECT("绿卡!B"&(INDIRECT("$L$13")+1))="事件",IF(INDIRECT("绿卡!D"&(INDIRECT("$L$13")+1))>0,INDIRECT("绿卡!D"&(INDIRECT("$L$13")+1)),"（无描述）"),"请刷新") -> （无描述）
B14: 蓝色生物 | C14: =COUNTIF(蓝卡!B:B,"生物") -> 93 | D14: /30 | E14: √ | J14: “公式”-“重新计算” | L14: =RANDBETWEEN(2,(LARGE(绿卡!A:A,1)+1)) -> 363 | M14: 概念 | N14: =IF(INDIRECT("绿卡!B"&(INDIRECT("$L$14")+1))="概念",INDIRECT("绿卡!C"&(INDIRECT("$L$14")+1)),"请刷新") -> 请刷新 | O14: =IF(INDIRECT("绿卡!B"&(INDIRECT("$L$14")+1))="概念",IF(INDIRECT("绿卡!D"&(INDIRECT("$L$14")+1))>0,INDIRECT("绿卡!D"&(INDIRECT("$L$14")+1)),"（无描述）"),"请刷新") -> 请刷新
B15: 紫色生物 | C15: =COUNTIF(紫卡!B:B,"生物") -> 43 | D15: /20 | E15: √ | L15: 蓝色品质
B16: 橙色生物 | C16: =COUNTIF(橙卡!B:B,"生物") -> 13 | D16: /9 | E16: √ | L16: 编号 | M16: 类型 | N16: 名称 | O16: 描述
B17: 虹色生物 | C17: =COUNTIF(虹卡!B:B,"生物") -> 4 | D17: /1 | E17: √ | L17: =RANDBETWEEN(2,(LARGE(蓝卡!A:A,1)+1)) -> 4 | M17: 生物 | N17: =IF(INDIRECT("蓝卡!B"&(INDIRECT("$L$17")+1))="生物",INDIRECT("蓝卡!C"&(INDIRECT("$L$17")+1)),"请刷新") -> 请刷新 | O17: =IF(INDIRECT("蓝卡!B"&(INDIRECT("$L$17")+1))="生物",IF(INDIRECT("蓝卡!D"&(INDIRECT("$L$17")+1))>0,INDIRECT("蓝卡!D"&(INDIRECT("$L$17")+1)),"（无描述）"),"请刷新") -> 请刷新
B18: 黑色生物 | C18: =COUNTIF(黑卡!B:B,"生物") -> 14 | L18: =RANDBETWEEN(2,(LARGE(蓝卡!A:A,1)+1)) -> 406 | M18: 器物 | N18: =IF(INDIRECT("蓝卡!B"&(INDIRECT("$L$18")+1))="器物",INDIRECT("蓝卡!C"&(INDIRECT("$L$18")+1)),"请刷新") -> 请刷新 | O18: =IF(INDIRECT("蓝卡!B"&(INDIRECT("$L$18")+1))="器物",IF(INDIRECT("蓝卡!D"&(INDIRECT("$L$18")+1))>0,INDIRECT("蓝卡!D"&(INDIRECT("$L$18")+1)),"（无描述）"),"请刷新") -> 请刷新
A19: 器物 | B19: =COUNTIF(白卡!B:B,"器物")+COUNTIF(绿卡!B:B,"器物")+COUNTIF(蓝卡!B:B,"器物")+COUNTIF(紫卡!B:B,"器物")+COUNTIF(橙卡!B:B,"器物")+COUNTIF(虹卡!B:B,"器物")+COUNTIF(黑卡!B:B,"器物") -> 257 | L19: =RANDBETWEEN(2,(LARGE(蓝卡!A:A,1)+1)) -> 249 | M19: 场所 | N19: =IF(INDIRECT("蓝卡!B"&(INDIRECT("$L$19")+1))="场所",INDIRECT("蓝卡!C"&(INDIRECT("$L$19")+1)),"请刷新") -> 请刷新 | O19: =IF(INDIRECT("蓝卡!B"&(INDIRECT("$L$19")+1))="场所",IF(INDIRECT("蓝卡!D"&(INDIRECT("$L$19")+1))>0,INDIRECT("蓝卡!D"&(INDIRECT("$L$19")+1)),"（无描述）"),"请刷新") -> 请刷新
B20: 白色器物 | C20: =COUNTIF(白卡!B:B,"器物") -> 72 | D20: /100 | E20: 严重不足 | L20: =RANDBETWEEN(2,(LARGE(蓝卡!A:A,1)+1)) -> 357 | M20: 事件 | N20: =IF(INDIRECT("蓝卡!B"&(INDIRECT("$L$20")+1))="事件",INDIRECT("蓝卡!C"&(INDIRECT("$L$20")+1)),"请刷新") -> 请刷新 | O20: =IF(INDIRECT("蓝卡!B"&(INDIRECT("$L$20")+1))="事件",IF(INDIRECT("蓝卡!D"&(INDIRECT("$L$20")+1))>0,INDIRECT("蓝卡!D"&(INDIRECT("$L$20")+1)),"（无描述）"),"请刷新") -> 请刷新
B21: 绿色器物 | C21: =COUNTIF(绿卡!B:B,"器物") -> 86 | D21: /40 | E21: √ | L21: =RANDBETWEEN(2,(LARGE(蓝卡!A:A,1)+1)) -> 167 | M21: 概念 | N21: =IF(INDIRECT("蓝卡!B"&(INDIRECT("$L$21")+1))="概念",INDIRECT("蓝卡!C"&(INDIRECT("$L$21")+1)),"请刷新") -> 请刷新 | O21: =IF(INDIRECT("蓝卡!B"&(INDIRECT("$L$21")+1))="概念",IF(INDIRECT("蓝卡!D"&(INDIRECT("$L$21")+1))>0,INDIRECT("蓝卡!D"&(INDIRECT("$L$21")+1)),"（无描述）"),"请刷新") -> 请刷新
B22: 蓝色器物 | C22: =COUNTIF(蓝卡!B:B,"器物") -> 51 | D22: /30 | E22: √ | L22: 紫色品质
B23: 紫色器物 | C23: =COUNTIF(紫卡!B:B,"器物") -> 31 | D23: /20 | E23: √ | L23: 编号 | M23: 类型 | N23: 名称 | O23: 描述
B24: 橙色器物 | C24: =COUNTIF(橙卡!B:B,"器物") -> 12 | D24: /9 | E24: √ | L24: =RANDBETWEEN(2,(LARGE(紫卡!A:A,1)+1)) -> 226 | M24: 生物 | N24: =IF(INDIRECT("紫卡!B"&(INDIRECT("$L$24")+1))="生物",INDIRECT("紫卡!C"&(INDIRECT("$L$24")+1)),"请刷新") -> 请刷新 | O24: =IF(INDIRECT("紫卡!B"&(INDIRECT("$L$24")+1))="生物",IF(INDIRECT("紫卡!D"&(INDIRECT("$L$24")+1))>0,INDIRECT("紫卡!D"&(INDIRECT("$L$24")+1)),"（无描述）"),"请刷新") -> 请刷新
B25: 虹色器物 | C25: =COUNTIF(虹卡!B:B,"器物") -> 4 | D25: /1 | E25: √ | L25: =RANDBETWEEN(2,(LARGE(紫卡!A:A,1)+1)) -> 161 | M25: 器物 | N25: =IF(INDIRECT("紫卡!B"&(INDIRECT("$L$25")+1))="器物",INDIRECT("紫卡!C"&(INDIRECT("$L$25")+1)),"请刷新") -> 请刷新 | O25: =IF(INDIRECT("紫卡!B"&(INDIRECT("$L$25")+1))="器物",IF(INDIRECT("紫卡!D"&(INDIRECT("$L$25")+1))>0,INDIRECT("紫卡!D"&(INDIRECT("$L$25")+1)),"（无描述）"),"请刷新") -> 请刷新
B26: 黑色器物 | C26: =COUNTIF(黑卡!B:B,"器物") -> 1 | L26: =RANDBETWEEN(2,(LARGE(紫卡!A:A,1)+1)) -> 25 | M26: 场所 | N26: =IF(INDIRECT("紫卡!B"&(INDIRECT("$L$26")+1))="场所",INDIRECT("紫卡!C"&(INDIRECT("$L$26")+1)),"请刷新") -> 请刷新 | O26: =IF(INDIRECT("紫卡!B"&(INDIRECT("$L$26")+1))="场所",IF(INDIRECT("紫卡!D"&(INDIRECT("$L$26")+1))>0,INDIRECT("紫卡!D"&(INDIRECT("$L$26")+1)),"（无描述）"),"请刷新") -> 请刷新
A27: 场所 | B27: =COUNTIF(白卡!B:B,"场所")+COUNTIF(绿卡!B:B,"场所")+COUNTIF(蓝卡!B:B,"场所")+COUNTIF(紫卡!B:B,"场所")+COUNTIF(橙卡!B:B,"场所")+COUNTIF(虹卡!B:B,"场所")+COUNTIF(黑卡!B:B,"场所") -> 305 | L27: =RANDBETWEEN(2,(LARGE(紫卡!A:A,1)+1)) -> 141 | M27: 事件 | N27: =IF(INDIRECT("紫卡!B"&(INDIRECT("$L$27")+1))="事件",INDIRECT("紫卡!C"&(INDIRECT("$L$27")+1)),"请刷新") -> 请刷新 | O27: =IF(INDIRECT("紫卡!B"&(INDIRECT("$L$27")+1))="事件",IF(INDIRECT("紫卡!D"&(INDIRECT("$L$27")+1))>0,INDIRECT("紫卡!D"&(INDIRECT("$L$27")+1)),"（无描述）"),"请刷新") -> 请刷新
B28: 白色场所 | C28: =COUNTIF(白卡!B:B,"场所") -> 84 | D28: /100 | E28: 严重不足 | L28: =RANDBETWEEN(2,(LARGE(紫卡!A:A,1)+1)) -> 161 | M28: 概念 | N28: =IF(INDIRECT("紫卡!B"&(INDIRECT("$L$28")+1))="概念",INDIRECT("紫卡!C"&(INDIRECT("$L$28")+1)),"请刷新") -> 请刷新 | O28: =IF(INDIRECT("紫卡!B"&(INDIRECT("$L$28")+1))="概念",IF(INDIRECT("紫卡!D"&(INDIRECT("$L$28")+1))>0,INDIRECT("紫卡!D"&(INDIRECT("$L$28")+1)),"（无描述）"),"请刷新") -> 请刷新
B29: 绿色场所 | C29: =COUNTIF(绿卡!B:B,"场所") -> 49 | D29: /40 | L29: 橙色品质
B30: 蓝色场所 | C30: =COUNTIF(蓝卡!B:B,"场所") -> 115 | D30: /30 | E30: √ | L30: 编号 | M30: 类型 | N30: 名称 | O30: 描述
B31: 紫色场所 | C31: =COUNTIF(紫卡!B:B,"场所") -> 28 | D31: /20 | E31: √ | L31: =RANDBETWEEN(2,(LARGE(橙卡!A:A,1)+1)) -> 25 | M31: 生物 | N31: =IF(INDIRECT("橙卡!B"&(INDIRECT("$L$31")+1))="生物",INDIRECT("橙卡!C"&(INDIRECT("$L$31")+1)),"请刷新") -> 请刷新 | O31: =IF(INDIRECT("橙卡!B"&(INDIRECT("$L$31")+1))="生物",IF(INDIRECT("橙卡!D"&(INDIRECT("$L$31")+1))>0,INDIRECT("橙卡!D"&(INDIRECT("$L$31")+1)),"（无描述）"),"请刷新") -> 请刷新
B32: 橙色场所 | C32: =COUNTIF(橙卡!B:B,"场所") -> 9 | D32: /9 | L32: =RANDBETWEEN(2,(LARGE(橙卡!A:A,1)+1)) -> 3 | M32: 器物 | N32: =IF(INDIRECT("橙卡!B"&(INDIRECT("$L$32")+1))="器物",INDIRECT("橙卡!C"&(INDIRECT("$L$32")+1)),"请刷新") -> 请刷新 | O32: =IF(INDIRECT("橙卡!B"&(INDIRECT("$L$32")+1))="器物",IF(INDIRECT("橙卡!D"&(INDIRECT("$L$32")+1))>0,INDIRECT("橙卡!D"&(INDIRECT("$L$32")+1)),"（无描述）"),"请刷新") -> 请刷新
B33: 虹色场所 | C33: =COUNTIF(虹卡!B:B,"场所") -> 14 | D33: /1 | E33: √ | L33: =RANDBETWEEN(2,(LARGE(橙卡!A:A,1)+1)) -> 7 | M33: 场所 | N33: =IF(INDIRECT("橙卡!B"&(INDIRECT("$L$33")+1))="场所",INDIRECT("橙卡!C"&(INDIRECT("$L$33")+1)),"请刷新") -> 请刷新 | O33: =IF(INDIRECT("橙卡!B"&(INDIRECT("$L$33")+1))="场所",IF(INDIRECT("橙卡!D"&(INDIRECT("$L$33")+1))>0,INDIRECT("橙卡!D"&(INDIRECT("$L$33")+1)),"（无描述）"),"请刷新") -> 请刷新
B34: 黑色场所 | C34: =COUNTIF(黑卡!B:B,"场所") -> 6 | L34: =RANDBETWEEN(2,(LARGE(橙卡!A:A,1)+1)) -> 15 | M34: 事件 | N34: =IF(INDIRECT("橙卡!B"&(INDIRECT("$L$34")+1))="事件",INDIRECT("橙卡!C"&(INDIRECT("$L$34")+1)),"请刷新") -> 神秘回归 | O34: =IF(INDIRECT("橙卡!B"&(INDIRECT("$L$34")+1))="事件",IF(INDIRECT("橙卡!D"&(INDIRECT("$L$34")+1))>0,INDIRECT("橙卡!D"&(INDIRECT("$L$34")+1)),"（无描述）"),"请刷新") -> 祂们回来了，剩下的不过都是副产品。
A35: 事件 | B35: =COUNTIF(白卡!B:B,"事件")+COUNTIF(绿卡!B:B,"事件")+COUNTIF(蓝卡!B:B,"事件")+COUNTIF(紫卡!B:B,"事件")+COUNTIF(橙卡!B:B,"事件")+COUNTIF(虹卡!B:B,"事件")+COUNTIF(黑卡!B:B,"事件") -> 524 | L35: =RANDBETWEEN(2,(LARGE(橙卡!A:A,1)+1)) -> 39 | M35: 概念 | N35: =IF(INDIRECT("橙卡!B"&(INDIRECT("$L$35")+1))="概念",INDIRECT("橙卡!C"&(INDIRECT("$L$35")+1)),"请刷新") -> 请刷新 | O35: =IF(INDIRECT("橙卡!B"&(INDIRECT("$L$35")+1))="概念",IF(INDIRECT("橙卡!D"&(INDIRECT("$L$35")+1))>0,INDIRECT("橙卡!D"&(INDIRECT("$L$35")+1)),"（无描述）"),"请刷新") -> 请刷新
B36: 白色事件 | C36: =COUNTIF(白卡!B:B,"事件") -> 89 | D36: /100 | E36: 严重不足 | L36: ☆☆虹色品质☆☆
B37: 绿色事件 | C37: =COUNTIF(绿卡!B:B,"事件") -> 177 | D37: /40 | E37: √ | L37: 编号 | M37: 类型 | N37: 名称 | O37: 描述
B38: 蓝色事件 | C38: =COUNTIF(蓝卡!B:B,"事件") -> 127 | D38: /30 | E38: √ | L38: =RANDBETWEEN(2,(LARGE(虹卡!A:A,1)+1)) -> 10 | M38: 生物 | N38: =IF(INDIRECT("虹卡!B"&(INDIRECT("$L$38")+1))="生物",INDIRECT("虹卡!C"&(INDIRECT("$L$38")+1)),"请刷新") -> 圣子 | O38: =IF(INDIRECT("虹卡!B"&(INDIRECT("$L$38")+1))="生物",IF(INDIRECT("虹卡!D"&(INDIRECT("$L$38")+1))>0,INDIRECT("虹卡!D"&(INDIRECT("$L$38")+1)),"（无描述）"),"请刷新") -> 祂来了。
B39: 紫色事件 | C39: =COUNTIF(紫卡!B:B,"事件") -> 73 | D39: /20 | E39: √ | L39: =RANDBETWEEN(2,(LARGE(虹卡!A:A,1)+1)) -> 14 | M39: 器物 | N39: =IF(INDIRECT("虹卡!B"&(INDIRECT("$L$39")+1))="器物",INDIRECT("虹卡!C"&(INDIRECT("$L$39")+1)),"请刷新") -> 请刷新 | O39: =IF(INDIRECT("虹卡!B"&(INDIRECT("$L$39")+1))="器物",IF(INDIRECT("虹卡!D"&(INDIRECT("$L$39")+1))>0,INDIRECT("虹卡!D"&(INDIRECT("$L$39")+1)),"（无描述）"),"请刷新") -> 请刷新
B40: 橙色事件 | C40: =COUNTIF(橙卡!B:B,"事件") -> 43 | D40: /9 | E40: √ | L40: =RANDBETWEEN(2,(LARGE(虹卡!A:A,1)+1)) -> 2 | M40: 场所 | N40: =IF(INDIRECT("虹卡!B"&(INDIRECT("$L$40")+1))="场所",INDIRECT("虹卡!C"&(INDIRECT("$L$40")+1)),"请刷新") -> 下北泽 | O40: =IF(INDIRECT("虹卡!B"&(INDIRECT("$L$40")+1))="场所",IF(INDIRECT("虹卡!D"&(INDIRECT("$L$40")+1))>0,INDIRECT("虹卡!D"&(INDIRECT("$L$40")+1)),"（无描述）"),"请刷新") -> 这里，大概就是希望开始的地方吧……！
...

Sheet 白卡
A1: 序号 | B1: 类型 | C1: 卡名 | D1: 叙述 | E1: 来源
A2: 1 | B2: 概念 | C2: 火 | E2: 炼金团
A3: 2 | B3: 概念 | C3: 土 | E3: 炼金团
A4: 3 | B4: 概念 | C4: 金 | E4: 炼金团
A5: 4 | B5: 概念 | C5: 水 | E5: 炼金团
A6: 5 | B6: 概念 | C6: 木 | E6: 炼金团
A7: 6 | B7: 器物 | C7: 火花 | E7: 炼金团
A8: 7 | B8: 器物 | C8: 容器 | D8: 埏埴以为器，当其无，有器之用。 | E8: 炼金团
A9: 8 | B9: 器物 | C9: 泥巴 | E9: 炼金团
A10: 9 | B10: 器物 | C10: 水蒸气 | E10: 炼金团
A11: 10 | B11: 器物 | C11: 泥坯 | E11: 炼金团
A12: 11 | B12: 器物 | C12: 石头 | E12: 炼金团
A13: 12 | B13: 器物 | C13: 金沙 | E13: 炼金团
A14: 13 | B14: 器物 | C14: 土堆 | E14: 炼金团
A15: 14 | B15: 器物 | C15: 树 | E15: 炼金团
A16: 15 | B16: 场所 | C16: 森林 | E16: 炼金团
A17: 16 | B17: 器物 | C17: 陶罐 | E17: 炼金团
A18: 17 | B18: 器物 | C18: 海带 | E18: 炼金团
A19: 18 | B19: 事件 | C19: 火灾 | E19: 炼金团
A20: 19 | B20: 器物 | C20: 腌海带 | E20: 炼金团
... A120: 119 | B120: 器物 | C120: 树苗 | E120: 炼金团
A121: 120 | B121: 事件 | C121: 沉岛 | D121: 岛又没啦！ | E121: 炼金团
A122: 121 | B122: 生物 | C122: 劫匪 | E122: 炼金团
A123: 122 | B123: 生物 | C123: 岛民 | E123: 炼金团
A124: 123 | B124: 器物 | C124: 自动售货机 | D124: 出售各种口味可乐…等等，为什么有百事？
A125: 124 | B125: 器物 | C125: 碳酸水枪 | D125: Biu~啊好粘——
A126: 125 | B126: 生物 | C126: 可口可乐搬运工 | D126: 我们不生产可乐，我们只是快乐的搬运工。
A127: 126 | B127: 事件 | C127: 巨龙传说 | D127: 这里流传着一个古老的童谣。
A128: 127 | B128: 事件 | C128: 无效祷告 | D128: 你所祈祷的神灵不在神国或已陨落，请稍后再试。
A129: 128 | B129: 事件 | C129: 水能的发现 | D129: 防洪蓄水，丰产富民。
A130: 129 | B130: 事件 | C130: 水能的滥用 | D130: 研究表明，这条江河的生态已经遭受了毁灭性破坏。
A131: 130 | B131: 事件 | C131: 大坝决堤 | D131: 水漫千里。
A132: 131 | B132: 事件 | C132: 灵光一闪 | D132: 个人、团体、企业、国家、世界。谁都不会拒绝这美妙的灵感！
A133: 132 | B133: 事件 | C133: 产能过剩 | D133: 这是危机，也是机遇。
A134: 133 | B134: 事件 | C134: 能源枯竭 | D134: 即使是可乐，也不是无穷无尽的。
A135: 134 | B135: 生物 | C135: 可乐狂热者 | D135: 胃病和蛀牙？喝了这一瓶再说！吨吨吨……
A136: 135 | B136: 概念 | C136: 数学
A137: 136 | B137: 器物 | C137: 宝箱 | E137: 神格祝愿
A138: 137 | B138: 概念 | C138: 解释权 | E138: 神格祝愿
A139: 138 | B139: 生物 | C139: 清道夫 | E139: 神格祝愿
...

Sheet 绿卡
A1: 序号 | B1: 类型 | C1: 卡名 | D1: 叙述 | E1: 来源
A2: 1 | B2: 概念 | C2: 执着 | D2: 字面意思，不达目的不放弃，说实话……有点可怕呢。
A3: 2 | B3: 概念 | C3: 幸运 | D3: 仿佛被上天眷顾。
A4: 3 | B4: 概念 | C4: 温暖 | D4: 每个被需要、被认同的瞬间。
A5: 4 | B5: 概念 | C5: 天圆地方 | D5: 朴素的世界观，但对他们而言是整个世界。
A6: 5 | B6: 概念 | C6: 梦 | D6: 嗯……你醒过来了吗？
A7: 6 | B7: 概念 | C7: 沉默 | D7: 蔓延的不语。
A8: 7 | B8: 场所 | C8: 第一学院 | D8: 朝闻道，夕可死。
A9: 8 | B9: 场所 | C9: 流浪厕所 | D9: 当地球危在旦夕之际，我们选择了用高能粪便世代飞船来逃离。
A10: 9 | B10: 场所 | C10: 不稳定的空间断层 | D10: 空间的另一面是什么？想去看看吗？
A11: 10 | B11: 场所 | C11: 龙和虫子的战场 | D11: 新的时代，霸主该更替了
A12: 11 | B12: 场所 | C12: 万门之地 | D12: 买两扇门打八折，买四扇送上门安装。
A13: 12 | B13: 场所 | C13: 碳酸制造厂 | D13: 生产汽水原料的大厂，所有机械全部是自动化！当然，动力是碳酸。
... A39: 38 | B39: 场所 | C39: 阿莱桑公寓 | D39: 存在于这里的只是某一个房间。或许有日历？
A40: 39 | B40: 器物 | C40: 魔法木炭 | E40: 炼金团
A41: 40 | B41: 器物 | C41: 滚烫的石头 | E41: 炼金团
A42: 41 | B42: 器物 | C42: 蒸汽机器人 | E42: 炼金团
A43: 42 | B43: 事件 | C43: 大洪水 | E43: 炼金团
A44: 43 | B44: 生物 | C44: 自律人偶 | E44: 炼金团
A45: 44 | B45: 事件 | C45: 核战争 | E45: 炼金团
A46: 45 | B46: 器物 | C46: 末日钟 | E46: 炼金团
A47: 46 | B47: 事件 | C47: 核裁军 | E47: 炼金团
A48: 47 | B48: 场所 | C48: 宇宙废墟 | E48: 炼金团
A49: 48 | B49: 生物 | C49: 变异人 | E49: 炼金团
A50: 49 | B50: 场所 | C50: 长城 | E50: 炼金团
A51: 50 | B51: 生物 | C51: 乔治奥威尔 | E51: 炼金团
... A54: 53 | B54: 器物 | C54: 食人海带 | E54: 炼金团
A55: 54 | B55: 生物 | C55: 手工达人 | D55: 刑部尚书耿 | E55: 炼金团
A56: 55 | B56: 器物 | C56: 蒸汽船 | E56: 炼金团
A57: 56 | B57: 生物 | C57: 网络偶像 | E57: 炼金团
A58: 57 | B58: 器物 | C58: 铁甲舰 | E58: 炼金团
A59: 58 | B59: 生物 | C59: 初音未来 | E59: 炼金团
A60: 59 | B60: 器物 | C60: 大炮巨舰 | E60: 炼金团
A61: 60 | B61: 器物 | C61: niconico | E61: 炼金团
A62: 61 | B62: 生物 | C62: 野兽先辈 | E62: 炼金团
A63: 62 | B63: 生物 | C63: 东风谷早苗 | E63: 炼金团
A64: 63 | B64: 器物 | C64: xilixili | E64: 炼金团
A65: 64 | B65: 器物 | C65: ACFUN | E65: 炼金团
A66: 65 | B66: 器物 | C66: bog匿名版 | E66: 炼金团
A67: 66 | B67: 生物 | C67: 王刚 | D67: 宽油 | E67: 炼金团
...

Sheet 蓝卡
A1: 序号 | B1: 类型 | C1: 卡名 | D1: 叙述 | E1: 来源
A2: 1 | B2: 事件 | C2: 情人节 | D2: 由单身狗的哀嚎和现充们的欢笑交织而成的一天。
A3: 2 | B3: 事件 | C3: 糟糕的一天 | D3: 详情请参考由DC出品的漫画《致命玩笑》。
A4: 3 | B4: 事件 | C4: 神棍的预言 | D4: 可信度极低的预言，但……也说不定。
A5: 4 | B5: 事件 | C5: 大碰撞 | D5: 大碰撞之后是毁灭还是新生？
A6: 5 | B6: 事件 | C6: 回归 | D6: 是什么事情使你回来呢？是死亡，还是新生?
A7: 6 | B7: 事件 | C7: 魔高一丈 | D7: 正不胜邪，这就是现实。
A8: 7 | B8: 事件 | C8: 灵感与火花 | D8: 上帝保佑，这真是一个绝妙的想法，我得找一张纸，或许还有墨水。
A9: 8 | B9: 概念 | C9: 绝望 | D9: 泯灭的生机、断绝的欲望、停滞的思考、黑暗的彼方
A10: 9 | B10: 概念 | C10: Waaagh | D10: 内边的技师小子！俺寻思把虾米的哒咔整到背后俺也能飞，俺寻思涂个红色就齐活叻。
A11: 10 | B11: 概念 | C11: 食人 | D11: 拜托，我可是文明人。
A12: 11 | B12: 概念 | C12: 中暑 | D12: 弱肉强食，一切借口都变得理所应当，甚至没有借口。
A13: 12 | B13: 概念 | C13: 挑战 | D13: 这是一场「试炼」，我认为这是一场让我战胜过去「试炼」，我接受了，只有在跨越那不成熟的过去后，拥有新的觉悟，人才能有所成长。
... A301: 300 | B301: 事件 | C301: 审判 | D301: 你不得不要为你所做的付出代价。
A302: 301 | B302: 器物 | C302: 世界树 | E302: 炼金团
A303: 302 | B303: 概念 | C303: 蒸汽动力 | E303: 炼金团
A304: 303 | B304: 器物 | C304: 末日机甲 | E304: 炼金团
A305: 304 | B305: 生物 | C305: 瓦特 | E305: 炼金团
A306: 305 | B306: 生物 | C306: 焦耳 | E306: 炼金团
A307: 306 | B307: 生物 | C307: 法拉第 | E307: 炼金团
A308: 307 | B308: 器物 | C308: 高达 | E308: 炼金团
A309: 308 | B309: 生物 | C309: 奥尔加团长 | E309: 炼金团
A310: 309 | B310: 生物 | C310: 富兰克林 | E310: 炼金团
A311: 310 | B311: 生物 | C311: 阿伏伽德罗 | E311: 炼金团
A312: 311 | B312: 生物 | C312: 特斯拉 | E312: 炼金团
A313: 312 | B313: 生物 | C313: 乔布斯 | E313: 炼金团
... A329: 328 | B329: 概念 | C329: 人民武装 | E329: 炼金团
A330: 329 | B330: 生物 | C330: 周树人 | D330: 鲁迅犯事了，关我周树人什么事 | E330: 炼金团
A331: 330 | B331: 器物 | C331: 可口的碳酸大炮 | D331: 让蓝色洁厕灵异端、透明雪碧蛮子和崂山鞋神教徒通通死在香草味的炮火下吧！
A332: 331 | B332: 器物 | C332: 多功能自动售货机 | D332: 紧急情况下，它可以提供充电、急救、避震防险等特殊服务。
A333: 332 | B333: 生物 | C333: 可口可乐研究员 | D333: 我们致力开发丰富多彩的口味以及看起来很划算的包装。
A334: 333 | B334: 事件 | C334: 巨龙降临 | D334: 传说中的生物，成为了现实。
A335: 334 | B335: 事件 | C335: 神光照耀 | D335: 神陨落前洒下的最后一点仁慈。
A336: 335 | B336: 事件 | C336: 电能的发现 | D336: 这或许要归功于一个放风筝的人。
A337: 336 | B337: 事件 | C337: 电能的滥用 | D337: 副作用是：断电成为了文明的最大焦虑。
A338: 337 | B338: 事件 | C338: 大停电 | D338: 一夜之间，经济瘫痪，国家崩溃。
A339: 338 | B339: 事件 | C339: 灵光三闪 | D339: 个人、团体、企业、国家、世界。谁都不会拒绝这美妙的灵感！
A340: 339 | B340: 事件 | C340: 产能过剩 | D340: 这是危机，也是机遇。
A341: 340 | B341: 事件 | C341: 能源枯竭 | D341: 即使是可乐，也不是无穷无尽的。
A342: 341 | B342: 生物 | C342: 可乐怪人 | D342: 人类对可乐的滥用终究导致了灾厄的诞生。着装碳酸动力甲的人们被与可乐深度融合，成为了丧失人性的破坏机械！
...

Sheet 紫卡
A1: 序号 | B1: 类型 | C1: 卡名 | D1: 叙述 | E1: 来源
A2: 1 | B2: 场所 | C2: 破败的皇家陵园 | D2: 被毁灭的国家的陵园，是贵族和王族的最终归宿，现在不过只是一个破败的陵园。陪葬品遭到盗窃，遗体遭到亵渎，能在这片陵园中感到恨意。
A3: 2 | B3: 场所 | C3: 巨兽脊背 | D3: 传说这片大地是在一只巨兽的脊背上，但好像这传说所言非虚……
A4: 3 | B4: 场所 | C4: 过去的圣地 | D4: 或许每一片草地都曾被奉作圣地。
A5: 4 | B5: 场所 | C5: 神农架 | D5: 先贤于此，救治万民，保佑楚地免受疫病。传说还有野人。
A6: 5 | B6: 场所 | C6: 停不下的兵工厂 | D6: 无尽的原料，无限大的仓库，不断制造武器的兵工厂。从科技侧的武器到神秘侧的武器，只要被称为武器的东西 里面都可以制造，每次出厂的武器都是随机的。
A7: 6 | B7: 场所 | C7: 帝乡 | D7: 确有其事，有传言，那里不属于人间，是历来追逐长生的仙人的故乡，也是奔流复回之地，因此求道者皆逐水而行。天行有常，水枯则惨，帝乡也仅余过去的辉煌。当香再次点起，烟传至四方，失源之人便会聚集起来，然非人在逐水，却水如鹰犬逐人。
A8: 7 | B8: 场所 | C8: 地图世界 | D8: 一张世界地图，但里面好像真的有一个世界……
A9: 8 | B9: 场所 | C9: 源之宫 | D9: 享受着腐败和奢靡乐趣的王公贵族，未曾设想过失却源水的未来。当破败和腐朽如走马般叩门，望族们不肯苟且于短暂的快乐，便造就了远离历史的华美之所，然，天行有常……
A10: 9 | B10: 场所 | C10: 瀛洲 | D10: 东海仙山，老子水多。
A11: 10 | B11: 场所 | C11: 疯狂地牢 | D11: 满地的陷阱，无数的怪物，无尽宝藏的谣言，但就是没有宝藏。
A12: 11 | B12: 场所 | C12: 庄周梦蝶 | D12: 这是无尽的梦境，一层叠一层。只有坠落才能醒来，但真的醒来了吗？
A13: 12 | B13: 场所 | C13: 月神梦境 | D13: 永生的月神设下永恒的幻梦，无知的猎人陷入杀戮之夜，在最后完成试炼，神子诞生。
... A157: 156 | B157: 概念 | C157: 咕 | D157: 又是可以摸鱼的一天呐，但好像总有点罪恶感是怎么回事呢？
A158: 157 | B158: 概念 | C158: 神话 | E158: 炼金团
A159: 158 | B159: 事件 | C159: 末日 | E159: 炼金团
A160: 159 | B160: 生物 | C160: 先知 | E160: 炼金团
A161: 160 | B161: 生物 | C161: 半神 | E161: 炼金团
A162: 161 | B162: 事件 | C162: 工业革命 | E162: 炼金团
A163: 162 | B163: 事件 | C163: 机械天灾 | E163: 炼金团
A164: 163 | B164: 事件 | C164: 神迹 | E164: 炼金团
A165: 164 | B165: 概念 | C165: 机械文明 | E165: 炼金团
A166: 165 | B166: 概念 | C166: 蜂群意识 | E166: 炼金团
A167: 166 | B167: 事件 | C167: 机械天灾 | E167: 炼金团
A168: 167 | B168: 器物 | C168: 充气糖浆导弹 | D168: 引爆可乐，甜云升天！
A169: 168 | B169: 器物 | C169: 自动售货机式防空炮 | D169: 它集防御外星人入侵和解渴功能于一身。
A170: 169 | B170: 生物 | C170: 可口可乐总裁 | D170: 谁掌控了可乐，谁就掌控了肥宅；谁掌控了肥宅，谁就掌控了未来。
A171: 170 | B171: 事件 | C171: 龙国建立 | D171: 拥有文明的巨龙将强大无比。
A172: 171 | B172: 事件 | C172: 神降 | D172: 神的灵被逼下尘世，寻找依附。
A173: 172 | B173: 事件 | C173: 核能的发现 | D173: 一种几乎无穷的能量——这是划时代的发现！
A174: 173 | B174: 事件 | C174: 核能的滥用 | D174: 又有什么关系呢？
A175: 174 | B175: 事件 | C175: 核灾爆发 | D175: 世界陷入了危机……再一次。
A176: 175 | B176: 事件 | C176: 灵光乱闪 | D176: 个人、团体、企业、国家、世界。谁都不会拒绝这美妙的灵感！
A177: 176 | B177: 事件 | C177: 产能过剩 | D177: 这是危机，也是机遇。
A178: 177 | B178: 事件 | C178: 能源枯竭 | D178: 即使是可乐，也不是无穷无尽的。
A179: 178 | B179: 生物 | C179: 可乐博士 | D179: 人体可乐化的实验，已经来到了最后一步……
A180: 179 | B180: 事件 | C180: 不死化 | E180: 神格祝愿
A181: 180 | B181: 器物 | C181: 双月 | E181: 神格祝愿
A182: 181 | B182: 器物 | C182: 星星 | E182: 神格祝愿
A183: 182 | B183: 生物 | C183: 人类 | E183: 神格祝愿
...

Sheet 橙卡
A1: 序号 | B1: 类型 | C1: 卡名 | D1: 叙述 | E1: 来源
A2: 1 | B2: 事件 | C2: 传奇 | D2: 将一张牌的颜色变为橙色。
A3: 2 | B3: 事件 | C3: 欺骗 | D3: 小孩子撒谎不做作业是欺骗，1999年的事也是欺骗。
A4: 3 | B4: 事件 | C4: 古城湮灭 | D4: 一座古城，被漫天黄沙吞噬了。或许数千年后，它隐藏的历史才可以重现光明。
A5: 4 | B5: 事件 | C5: 牌中世界 | D5: 抽牌，出牌，比肩神明，绝妙的想法，但你不可否认，我们也有可能是牌桌上的筹码。
A6: 5 | B6: 事件 | C6: 黑死病 | D6: 不是自然的选择，而是神秘学上灾厄的化身——魔王于此降临。
A7: 6 | B7: 事件 | C7: 回归之兽 | D7: 苏美尔母神回归。人子啊，遵从起源之声——
A8: 7 | B8: 事件 | C8: 最后的陨落 | D8: 无尽的坠落。
A9: 8 | B9: 事件 | C9: 启示录 | D9: 有权柄赐给他们，可以用刀剑、饥荒、瘟疫、野兽，杀害地上四分之一的人。
A10: 9 | B10: 事件 | C10: 死者苏生 | D10: 他们从坟墓里爬出来了。他们……回来了。那是……逆反生死的超大炼金术！
A11: 10 | B11: 事件 | C11: 反转 | D11: 颠覆常理的大逆转 。
A12: 11 | B12: 事件 | C12: 岩浆雨 | D12: 细密如雨，猩红似血。生灵弹指间灰飞烟灭。绝望、哭喊、恐惧戛然而止，地动山摇化作一片寂静。
A13: 12 | B13: 事件 | C13: 大赦 | D13: 新皇登基，大赦天下。 无数狱中囚徒、劳苦农奴重获自由，重见天日。摆脱命运的他们，却仍然是蝼蚁。
... A20: 19 | B20: 事件 | C20: 战争 | D20: War.War never changes.
A21: 20 | B21: 概念 | C21: 神明 | E21: 炼金团
A22: 21 | B22: 生物 | C22: 水神 | E22: 炼金团
A23: 22 | B23: 事件 | C23: 审判日 | E23: 炼金团
A24: 23 | B24: 事件 | C24: 大灭绝 | E24: 炼金团
A25: 24 | B25: 事件 | C25: XK级末日 | E25: 炼金团
A26: 25 | B26: 概念 | C26: 传说 | E26: 炼金团
A27: 26 | B27: 概念 | C27: 万物归一 | E27: 炼金团
A28: 27 | B28: 生物 | C28: 齐天大圣 | D28: 你知道他是谁。
A29: 28 | B29: 器物 | C29: 冈格尼尔之枪 | D29: 没有人能逃过命运。
A30: 29 | B30: 概念 | C30: 逆转 | D30: 化不可能为可能，转可能为不可能，既创造奇迹亦扼杀奇迹，既颠倒是非亦拨正黑白！
A31: 30 | B31: 场所 | C31: 尤克特拉希尔 | D31: 尼德霍格不在这里吧？
A32: 31 | B32: 生物 | C32: 神……小姐？ | D32: 你你你！你快放开我啊喂，我不是什么Ap……总而言之！快把我从这张卡里放出去！
A33: 32 | B33: 场所 | C33: 神圣的大陆 | D33: 安洁之地，应许无疆
A34: 33 | B34: 事件 | C34: 诸神黄昏 | D34: 现在，轮到你们了！
A35: 34 | B35: 事件 | C35: 英雄出场 | D35: 让你们久等了，一切都交给我吧，我来结束这一切！
A36: 35 | B36: 概念 | C36: 雷加鲁克 | D36: 必将应验的终末预言。
A37: 36 | B37: 概念 | C37: 有始有终 | D37: 有开始，就会有结束。失散不是结局，坠落不是开始。
A38: 37 | B38: 器物 | C38: 黑铁囚笼 | D38: 一个没有锁的笼子，但是你永远无法从内部打开它。
A39: 38 | B39: 器物 | C39: SCP-294 | D39: 你不会真的只用它点咖啡吧？
... A72: 71 | B72: 生物 | C72: 可乐人 | D72: 它，即是世间所有可乐的人格化！
A73: 72 | B73: 生物 | C73: 半神 | E73: 神格祝愿
A74: 73 | B74: 概念 | C74: 乌托邦 | E74: 神格祝愿
A75: 74 | B75: 概念 | C75: 多 | E75: 神格祝愿
A76: 75 | B76: 事件 | C76: 理解神明本质 | E76: 神格祝愿
A77: 76 | B77: 事件 | C77: 奇迹 | E77: 神格祝愿
A78: 77 | B78: 器物 | C78: 通天桥 | E78: 神格祝愿
...

Sheet 虹卡
A1: 序号 | B1: 类型 | C1: 卡名 | D1: 叙述 | E1: 来源
A2: 1 | B2: 事件 | C2: 肃正协议 | E2: 炼金团
A3: 2 | B3: 场所 | C3: 下北泽 | D3: 这里，大概就是希望开始的地方吧……！
A4: 3 | B4: 事件 | C4: 乐园计划 | D4: 制造一场能毁灭90%的人的灾变，再加上被牢牢控制住的绿洲和解药，神就是这样诞生的。。
A5: 4 | B5: 事件 | C5: 新时代 | D5: 老旧的古董只会被扫到历史的垃圾堆里，今时已不再同往日了！
A6: 5 | B6: 事件 | C6: 开天辟地 | D6: 天地混沌如鸡子，盘古生在其中，万八千岁，天地开辟，阳清为天，阴浊为地，盘古在其中。
A7: 6 | B7: 场所 | C7: 黑洞 | D7: 这是终焉还是新天地？
A8: 7 | B8: 生物 | C8: 孔雀明王 | D8: 佛母。
A9: 8 | B9: 场所 | C9: 放……人造世界9999号的投影 | D9: 嘁，我把我的世界照过来了，以后经常来找我玩啊，还有！不要叫我神小姐！我叫艾萝丝，给我好好的记住了啊
A10: 9 | B10: 事件 | C10: 花开之日 | D10: 至少……结局还算美好。
A11: 10 | B11: 生物 | C11: 圣子 | D11: 祂来了。
A12: 11 | B12: 器物 | C12: 暂停键 | D12: 老旧随身听上拆下来的按键。被遗忘在某个抽屉里。没了外壳的按键要怎样才能按得下去呢。
A13: 12 | B13: 器物 | C13: 如意 | D13: 如意如意，随我心意，快快显灵。
A14: 13 | B14: 概念 | C14: 逍遥 | D14: 至人无己，神人无功，圣人无名。
... A25: 24 | B25: 器物 | C25: 人鱼蜡 | D25: 古墓墓道中的长明灯，借以盗墓人的意志燃烧，还以所期待的和所幻想的美梦。
A26: 25 | B26: 概念 | C26: 女体化 | E26: 神格祝愿
A27: 26 | B27: 概念 | C27: 同性生育 | E27: 神格祝愿
A28: 27 | B28: 概念 | C28: 幸福 | E28: 神格祝愿
A29: 28 | B29: 事件 | C29: 成神 | E29: 神格祝愿
A30: 29 | B30: 场所 | C30: 道场 | D30: 悟道之地。
A31: 30 | B31: 场所 | C31: 异界勇者召唤法阵 | D31: “啊？怎么这次又是日本高中生？”
A32: 31 | B32: 场所 | C32: 伊甸园 | D32: 最初的乐园。
A33: 32 | B33: 场所 | C33: 镀金玫瑰酒馆 | D33: 一切传说人物诞生的起点。
A34: 33 | B34: 场所 | C34: 终焉沙漠 | D34: 这里没有沙子，只有绝望。
A35: 34 | B35: 场所 | C35: 万灵宗 | D35: “从今日起，修真界唯我万灵宗马首是瞻。”
A36: 35 | B36: 场所 | C36: 肉山 | D36: 它们一无所有。
A37: 36 | B37: 场所 | C37: 方舟号 | D37: 这是最后的希望。
A38: 37 | B38: 场所 | C38: 巨剑 | D38: 一把插入大地的巨剑，历经岁月磨洗，仿佛在等一个故事。
A39: 38 | B39: 场所 | C39: 断罪小学 | D39: 一所位于狼牙区飞虎路的私立学校。

Sheet 黑卡
A1: 序号 | B1: 类型 | C1: 卡名 | D1: 叙述 | E1: 来源
A2: 1 | B2: 生物 | C2: 巨神兵 | D2: 这不是怪兽，是神！
A3: 2 | B3: 生物 | C3: 第四天灾 | D3: 一切的元凶，我们维度之上的存在。
A4: 3 | B4: 生物 | C4: 虚无 | D4: 概念尚未出现时，这是世界上唯一存在的。
A5: 4 | B5: 生物 | C5: 剧本家 | D5: 万物必会随祂的剧本而行动。
A6: 5 | B6: 生物 | C6: 太一 | D6: 祂于万物中。
A7: 6 | B7: 生物 | C7: 所罗门 | D7: 诞生之时到来，其为修缮万物者（Ars Paulina），戴冠之时到来，其为创始万物者（Ars Almadel Salomonis），诀别之时到来。其为放手世界者（Ars Nova）。神秘学始祖，也是神的代言人，更是人类的解放者。
A8: 7 | B8: 概念 | C8: 爱 | D8: 刻骨铭心。
A9: 8 | B9: 生物 | C9: 猶格·索托斯 | D9: 鑰匙和門,一生萬物，萬物歸一者,虛空之扉的超越者。如果能取悅它的話，它可能會賜以知識作報償。“人的天才只是火花，要想使它成熊熊火焰，哪就只有學習！學習！！！”
A10: 9 | B10: 生物 | C10: 毒龙 | D10: 不会钻，但同样致命。
A11: 10 | B11: 场所 | C11: 镜湖 | D11: 云，天，湖，还有你。
A12: 11 | B12: 生物 | C12: 赛博人的虚拟偶像 | D12: 人造的亚空间之神，是钥匙，也是情感的寄托赛博人会信仰电子神明吗？
A13: 12 | B13: 器物 | C13: 武器 | D13: 区别于工具的另一种人造物品，从它诞生开始就被赋予了最高的恶意。
... A26: 25 | B26: 生物 | C26: 脚男 | D26: 上上次是巨龙，上次是古神，怎么还是你？
A27: 26 | B27: 概念 | C27: 调零 | E27: 神格祝愿
A28: 27 | B28: 事件 | C28: 时间崩塌 | E28: 神格祝愿
A29: 28 | B29: 事件 | C29: 时间湮灭 | E29: 神格祝愿
A30: 29 | B30: 概念 | C30: 希望 | E30: 神格祝愿
A31: 30 | B31: 生物 | C31: 阿撒托斯 | D31: 世界是祂的梦
A32: 31 | B32: 生物 | C32: 奈亚拉托提普 | D32: 那些盲目、喑哑、痴愚的蕃神们——正缓慢、笨拙、荒谬地跳起舞蹈。而它们的灵魂就是奈亚拉托提普。
A33: 32 | B33: 生物 | C33: 纱布尼古拉斯 | D33: “黑暗丰穰之女神”、“至高母神”、“孕育万千子孙的森之黑山羊”
